Workbook
Name BatCostIDR: Assumptions!$E$28
Name BatCostUSD: Assumptions!$E$13
Name BatDegradation: Assumptions!$E$24
Name BatteriesRow: Assumptions!$B$46:$F$46
Name CapexInfl: Assumptions!$E$12
Name CarbonMonetization: Assumptions!$E$35
Name CarbonPriceID: Assumptions!$E$15
Name CarbonPriceUSD: Assumptions!$E$16
Name Churn: Assumptions!$E$27
Name CourierGrowth: Assumptions!$E$23
Name CouriersPerHub: Assumptions!$B$44:$F$44
Name DieselPrice: Assumptions!$E$14
Name EVGrowth: Assumptions!$E$22
Name FX: Assumptions!$E$11
Name HomesPerMG: Assumptions!$B$45:$F$45
Name HubCapex: Assumptions!$E$31
Name HubsRow: Assumptions!$B$42:$F$42
Name HubsY1: Assumptions!$E$36
Name HubUtilization: Assumptions!$E$25
Name Inflation: Assumptions!$E$9
Name MicroCapex: Assumptions!$E$32
Name MicrogridsRow: Assumptions!$B$43:$F$43
Name MicrogridsY1: Assumptions!$E$37
Name MicrogridUptime: Assumptions!$E$26
Name MicroPrice: Assumptions!$E$30
Name OEMARPU: Assumptions!$E$34
Name OEMcustomers: Assumptions!$B$47:$F$47
Name PassportARPU: Assumptions!$E$33
Name Scenario: Assumptions!$B$4
Name ScenIdx: Assumptions!$B$5
Name SwapPrice: Assumptions!$E$29
Name TaxRate: Assumptions!$E$17
Name WACC: Assumptions!$E$10

Sheet Contents
A1: VOLTLOOP — CONTENTS
A2: Click any sheet to open. Grouped by section.
A4: NAVIGATION & CONTROL
A5: Contents
A6: Reading Guide
A7: Model Checks
A8: FD_Decision_Log
A10: FINANCE MODEL
A11: Funding_Plan
A12: BreakEven_Bridge
A13: Valuation
A14: Sensitivity_Y5_Breakeven
... A100: Tropical_Test_Protocol

Sheet Funding_Plan
A1: VOLTLOOP — FUNDING PLAN (close the cash gap, blended financing)
A2: All values IDR. Blue = [Assumption] input (founder-adjustable). New funding sized so ending cash ≥ buffer every year. Drives Cash Flow rows 16-17.
C3: Y1 | D3: Y2 | E3: Y3 | F3: Y4 | G3: Y5 | H3: 5-Yr Total
A4: EXISTING FUNDING (original model)
A5: Existing equity raises [Original] | C5: 3500000000 | D5: 6000000000 | E5: 20000000000 | F5: 30000000000 | G5: 0 | H5: =SUM(C5:G5) -> 59500000000
A6: Existing debt raises [Original] | C6: 0 | D6: 2000000000 | E6: 5000000000 | F6: 8000000000 | G6: 10000000000 | H6: =SUM(C6:G6) -> 25000000000
A7: Existing total funding | C7: =C5+C6 -> 3500000000 | D7: =D5+D6 -> 8000000000 | E7: =E5+E6 -> 25000000000 | F7: =F5+F6 -> 38000000000 | G7: =G5+G6 -> 10000000000 | H7: =SUM(C7:G7) -> 84500000000
A8: Ending cash — original plan [reference snapshot] | C8: -250331294 | D8: -1436375808 | E8: 110502065 | F8: 8019105963 | G8: -10116411077 | H8: =MIN(C8:G8) -> -10116411077
A9: - Min ending cash (original) | C9: =MIN(C8:G8) -> -10116411077
A11: NEW FUNDING REQUIRED (audit fix — blended)
A12: Target minimum cash buffer [Assumption] | C12: 3000000000 | D12: - floor applied to every year's ending cash
A13: New equity raise [Assumption] | C13: 3500000000 | D13: 1500000000 | E13: 0 | F13: 0 | G13: 6000000000 | H13: =SUM(C13:G13) -> 11000000000
A14: New debt facility [Assumption] | C14: 0 | D14: 0 | E14: 0 | F14: 0 | G14: 2500000000 | H14: =SUM(C14:G14) -> 2500000000
A15: New asset financing (battery-backed) [Assumption] | C15: 0 | D15: 0 | E15: 0 | F15: 0 | G15: 2000000000 | H15: =SUM(C15:G15) -> 2000000000
A16: Total new funding | C16: =SUM(C13:C15) -> 3500000000 | D16: =SUM(D13:D15) -> 1500000000 | E16: =SUM(E13:E15) -> 0 | F16: =SUM(F13:F15) -> 0 | G16: =SUM(G13:G15) -> 10500000000 | H16: =SUM(C16:G16) -> 15500000000
A17: Cumulative new funding | C17: =C16 -> 3500000000 | D17: =C17+D16 -> 5000000000 | E17: =D17+E16 -> 5000000000 | F17: =E17+F16 -> 5000000000 | G17: =F17+G16 -> 15500000000 | H17: =SUM(C17:G17) -> 34000000000
A19: PRO-FORMA FUNDING (feeds Cash Flow)
A20: Total equity raises (existing + new) - CF row 16 | C20: =C5+C13 -> 7000000000 | D20: =D5+D13 -> 7500000000 | E20: =E5+E13 -> 20000000000 | F20: =F5+F13 -> 30000000000 | G20: =G5+G13 -> 6000000000 | H20: =SUM(C20:G20) -> 70500000000
A21: Total debt raises (existing + facility + asset fin) - CF row 17 | C21: =C6+C14+C15 -> 0 | D21: =D6+D14+D15 -> 2000000000 | E21: =E6+E14+E15 -> 5000000000 | F21: =F6+F14+F15 -> 8000000000 | G21: =G6+G14+G15 -> 14500000000 | H21: =SUM(C21:G21) -> 29500000000
A22: Pro-forma ending cash (live from Cash Flow) | C22: ='Cash Flow'!C22 -> 3.2496687e+09 | D22: ='Cash Flow'!D22 -> 4.5624008e+09 | E22: ='Cash Flow'!E22 -> 8.7723979e+09 | F22: ='Cash Flow'!F22 -> 2.1340017e+10 | G22: ='Cash Flow'!G22 -> 2.0109811e+10 | H22: =MIN(C22:G22) -> 3.2496687e+09
A23: - Min ending cash (pro-forma) — must be ≥ buffer | C23: =MIN(C22:G22) -> 3.2496687e+09 | E23: =IF(MIN(C22:G22)>=C12,"OK above buffer",IF(MIN(C22:G22)>=0,"OK but thin","FAIL — still negative")) -> OK above buffer
A25: FUNDING SUFFICIENCY
A26: Cumulative funding (equity+debt, pro-forma) | C26: =C20+C21 -> 7000000000 | D26: =C26+D20+D21 -> 16500000000 | E26: =D26+E20+E21 -> 41500000000 | F26: =E26+F20+F21 -> 79500000000 | G26: =F26+G20+G21 -> 100000000000
A27: Gross PP&E deployed (cumulative) | C27: ='Balance Sheet'!C10 -> 2.6798955e+09 | D27: ='Balance Sheet'!D10 -> 9.1387726e+09 | E27: ='Balance Sheet'!E10 -> 2.8321152e+10 | F27: ='Balance Sheet'!F10 -> 5.6838415e+10 | G27: ='Balance Sheet'!G10 -> 9.1327074e+10
A28: Funding surplus / (gap) — must be ≥ 0 | C28: =C26-C27 -> 4.3201045e+09 | D28: =D26-D27 -> 7.3612274e+09 | E28: =E26-E27 -> 1.3178848e+10 | F28: =F26-F27 -> 2.2661585e+10 | G28: =G26-G27 -> 8.6729261e+09
A29: Status | C29: =IF(MIN(C28:G28)>=0,"OK fully funded","GAP remains") -> OK fully funded
A31: DILUTION IMPACT (incremental round, this audit)
A32: Pre-money valuation [Assumption] | C32: 120000000000 | D32: - placeholder; refine from Valuation sheet (FD-03)
A33: New equity raised (this round, cumulative) | C33: =H13 -> 11000000000
A34: Post-money valuation | C34: =C32+C33 -> 131000000000
A35: New investor ownership % | C35: =C33/C34 -> 0.083969466
A36: Existing shareholders ownership % (post) | C36: =1-C35 -> 0.91603053
A37: Note | C37: Incremental dilution on the NEW Rp 11B equity only. Prior rounds (Rp 59.5B) already in the cap table; full cap table lives in Investor Returns.

Sheet Reading Guide
A1: VOLTLOOP — READING GUIDE
A2: How to read this workbook: a 5-minute path for a first look, then the full build order. Click any sheet name to jump.
A4: 5-MINUTE INVESTOR PATH
A5: Step | B5: Sheet | C5: What it answers
A6: 1 | B6: Exec_Fin_Dashboard | C6: The whole picture: revenue, EBITDA, cash, NPV, finance score
A7: 2 | B7: 01_Executive_Overview | C7: The pitch: problem, solution, market, why now
A8: 3 | B8: Cohort_Economics | C8: Does ONE mature hub make money? (the core question)
A9: 4 | B9: BreakEven_Bridge | C9: How Y5 net income reaches break-even (+Rp0.89B) — TARGET, driven by assumed operating levers (not yet pilot-proven)
A10: 5 | B10: Funding_Plan | C10: Is the cash enough? Funding gap closed, buffer held
A11: 6 | B11: FD_Decision_Log | C11: What decisions are still open before scaling
A13: FULL BUILD ORDER (how the model flows, left to right)
A14: # | B14: Section / lead sheet | C14: What it covers
A15: 1 | B15: Contents | C15: Index of all sheets & how to read this workbook
A16: 2 | B16: Contents | C16: Index of all sheets by section
A17: 3 | B17: 01_Executive_Overview | C17: Business story: problem, solution, target market
A18: 4 | B18: Market | C18: Problem, market size (TAM/SAM/SOM), customers, competitors
A19: 5 | B19: System_Architecture | C19: Product & technology: VoltSwap, VoltOS, VoltSmart, VoltGrid + BOMs
A20: 6 | B20: Assumptions | C20: The input engine — every key driver lives here
A21: 7 | B21: Revenue Model | C21: How money is made: price × volume, per stream
A22: 8 | B22: Swap Hub Econ | C22: Unit economics per hub & microgrid (feeds Cohort_Economics)
A23: 9 | B23: Cost_Drivers | C23: Cost structure (COGS, opex) and Capex Schedule
A24: 10 | B24: P&L | C24: Income statement → Cash Flow → Balance Sheet (3-statement, linked)
A25: 11 | B25: Funding_Plan | C25: Funding plan: blended financing closes the cash gap + buffer
A26: 12 | B26: BreakEven_Bridge | C26: FD-11: assumed operating levers that take Y5 NI from -5.5B to +0.9B (target, not pilot-proven)
... A30: 16 | B30: Assumptions_Log | C30: Audit trail: Assumptions_Log (every assumption, source, status), Change_Log (every edit), FD_Decision_Log (open decisions)
A32: BOTTOM LINE
A33: Capex-heavy energy-infrastructure bet, not a 5-year profit story. Funding gap is closed ON PLAN (assumes the Rp11B equity + Rp4.5B debt raise is completed). Y5 net income reaches break-even (+Rp0.9B) and EBITDA turns positive from Y3 ONLY IF the +Rp6.66B operating levers prove out — today these are assumptions, not pilot data. The gating risk: one mature hub still loses money at base (-Rp93.6M/yr); scale only after hub EBITDA > 0. Valuation is almost entirely terminal-value-driven (NPV excluding terminal is negative), and at the current Rp120B pre-money the investor MOIC is below 1x in every scenario. Verdict: worth an angel/seed conversation; NOT institutional-ready until (1) hub economics are proven, (2) the break-even levers are validated, and (3) pre-money is aligned to intrinsic value.
A35: KEY RISKS — READ BEFORE THE NUMBERS
A36: 1. Valuation ~100% terminal-dependent: NPV excluding terminal value is negative (-Rp46B). Enterprise value is positive only because of the terminal/exit value.
A37: 2. Investor MOIC < 1x in ALL scenarios at the current Rp120B pre-money (Base 0.29x). Entry valuation must come down toward intrinsic equity (~Rp38B base) for investors to make money.
A38: 3. Y5 break-even and EBITDA-positive-from-Y3 both depend on +Rp6.66B operating levers labelled [Assumption] (VoltOS/VoltSmart, anchor fleet, opex, battery lifecycle) — not yet validated in a pilot.
A39: 4. One mature hub still loses money at base case (-Rp93.6M/yr). Expansion is gated until mature-hub EBITDA turns positive; target case shows +Rp255.9M/hub is reachable.
A40: 5. Funding sufficiency and 'no negative cash' hold ON PLAN — they assume the new raise is completed. Numbers are model outputs; figures sourced from the pitch deck are unchanged.
A41: 6. Model ties to the pitch deck: revenue, COGS, EBITDA, break-even Year 3, NI-positive Year 5, and min cash all MATCH (see Deck_Reconciliation). Two deck claims are NOT reproduced: net margin 36% (model ~1.4% after D&A) and the larger ~Rp122B funding ask.

Sheet Valuation
A1: VOLTLOOP — 5-YEAR DCF VALUATION (with & without terminal value)
A2: Infrastructure-style valuation: long-lived assets, terminal/exit value at Y5. Blue = [Assumption]. References live P&L, Capex, Balance Sheet.
A4: WACC BUILD-UP (CAPM / Damodaran)
A5: Risk-free rate — Indonesia 10Y govt [Assumption] | C5: 0.068 | D5: Bank Indonesia / IBPA INDOGB 10Y — verify dated
A6: Equity risk premium — Indonesia [Assumption] | C6: 0.085 | D6: Damodaran country ERP (Indonesia)
A7: Levered beta [Assumption] | C7: 1.3 | D7: Energy-infra / early-stage proxy
A8: Cost of equity = rf + β×ERP | C8: =C5+C7*C6 -> 0.1785
A9: Pre-tax cost of debt [Assumption] | C9: 0.11
A10: Tax rate (live = TaxRate) | C10: =TaxRate -> 0.22
A11: After-tax cost of debt | C11: =C9*(1-C10) -> 0.0858
A12: Target equity weight [Assumption] | C12: 0.7
A13: Target debt weight | C13: =1-C12 -> 0.3
A14: WACC (build-up) - used in DCF | C14: =C12*C8+C13*C11 -> 0.15069
A15: Model named WACC (Assumptions) — reference | C15: =WACC -> 0.12 | D15: Note: build-up (~15%) > model 12%. DCF uses build-up; recommend aligning Assumptions!E10.
A17: FREE CASH FLOW TO FIRM (FCFF) — IDR
C18: Y1 | D18: Y2 | E18: Y3 | F18: Y4 | G18: Y5
A19: EBIT (operating income) | C19: ='P&L'!C18 -> -1.2178974e+09 | D19: ='P&L'!D18 -> -2.4478018e+09 | E19: ='P&L'!E18 -> -4.2105059e+09 | F19: ='P&L'!F18 -> -2.7665451e+09 | G19: ='P&L'!G18 -> 2.6437721e+09
A20: Less: cash tax on EBIT (0 if EBIT<0) | C20: =-MAX(0,C19)*$C$10 -> 0 | D20: =-MAX(0,D19)*$C$10 -> 0 | E20: =-MAX(0,E19)*$C$10 -> 0 | F20: =-MAX(0,F19)*$C$10 -> 0 | G20: =-MAX(0,G19)*$C$10 -> -5.8162986e+08
A21: NOPAT | C21: =C19+C20 -> -1.2178974e+09 | D21: =D19+D20 -> -2.4478018e+09 | E21: =E19+E20 -> -4.2105059e+09 | F21: =F19+F20 -> -2.7665451e+09 | G21: =G19+G20 -> 2.0621422e+09
A22: Plus: D&A | C22: =-'P&L'!C17 -> 5.4423206e+08 | D22: =-'P&L'!D17 -> 1.778252e+09 | E22: =-'P&L'!E17 -> 5.2245451e+09 | F22: =-'P&L'!F17 -> 1.0205055e+10 | G22: =-'P&L'!G17 -> 1.6331973e+10
A23: Less: Capex | C23: =-'Capex Schedule'!C11 -> -2.6798955e+09 | D23: =-'Capex Schedule'!D11 -> -6.4588771e+09 | E23: =-'Capex Schedule'!E11 -> -1.918238e+10 | F23: =-'Capex Schedule'!F11 -> -2.8517263e+10 | G23: =-'Capex Schedule'!G11 -> -3.4488659e+10
A24: Less: Δ net working capital (cash effect) | C24: ='Cash Flow'!C8 -> -1.9677041e+08 | D24: ='Cash Flow'!D8 -> -7.5884097e+08 | E24: ='Cash Flow'!E8 -> -2.0216623e+09 | F24: ='Cash Flow'!F8 -> -3.2536279e+09 | G24: ='Cash Flow'!G8 -> -4.1656628e+09
A25: FCFF | C25: =C21+C22+C23+C24 -> -3.5503313e+09 | D25: =D21+D22+D23+D24 -> -7.8872679e+09 | E25: =E21+E22+E23+E24 -> -2.0190003e+10 | F25: =F21+F22+F23+F24 -> -2.4332381e+10 | G25: =G21+G22+G23+G24 -> -2.0260206e+10
A26: Discount period (yrs) | C26: 1 | D26: 2 | E26: 3 | F26: 4 | G26: 5
A27: Discount factor @ WACC | C27: =1/(1+$C$14)^C26 -> 0.86904379 | D27: =1/(1+$C$14)^D26 -> 0.75523711 | E27: =1/(1+$C$14)^E26 -> 0.65633412 | F27: =1/(1+$C$14)^F26 -> 0.57038309 | G27: =1/(1+$C$14)^G26 -> 0.49568789
A28: PV of FCFF | C28: =C25*C27 -> -3.0853934e+09 | D28: =D25*D27 -> -5.9567574e+09 | E28: =E25*E27 -> -1.3251388e+10 | F28: =F25*F27 -> -1.3878779e+10 | G28: =G25*G27 -> -1.0042739e+10
A30: Sum PV of explicit FCFF = NPV WITHOUT terminal value | C30: =SUM(C28:G28) -> -4.6215056e+10
A32: TERMINAL / EXIT VALUE
A33: Exit EV/EBITDA multiple — base [Assumption] | C33: 10 | D33: High-growth energy infra; Y5 EBITDA still ramping
A34: Y5 EBITDA (live) | C34: ='P&L'!G15 -> 1.8975745e+10
A35: Terminal value (exit multiple) = mult × Y5 EBITDA | C35: =C33*C34 -> 1.8975745e+11
A36: PV of terminal value @ WACC | C36: =C35*G27 -> 9.406047e+10
A37: Perpetuity growth g [Assumption] | C37: 0.03
A38: TV (perpetuity, Gordon) = FCFF₅×(1+g)/(WACC−g) | C38: =G25*(1+C37)/(C14-C37) -> -1.7290589e+11
A39: PV of TV (perpetuity) | C39: =C38*G27 -> -8.5707357e+10
A40: Note | C40: Perpetuity is NOT meaningful while Y5 FCFF is negative (capex still ramping). Exit-multiple method is the primary basis.
A42: ENTERPRISE & EQUITY VALUE (base, exit-multiple)
A43: PV of explicit FCFF (Y1-Y5) | C43: =C30 -> -4.6215056e+10
A44: PV of terminal value | C44: =C36 -> 9.406047e+10
A45: Enterprise Value = NPV WITH terminal value | C45: =C43+C44 -> 4.7845414e+10
...

Sheet Model Checks
A1: VOLTLOOP — MODEL INTEGRITY CHECKS
A2: Live linkage and integrity checks across the three statements. Status updates automatically.
A4: # | B4: Check | C4: Basis | D4: Result | E4: Status
A5: 1 | B5: Balance Sheet balances (Assets = Liab + Equity), all 5 years | C5: Max |check| | D5: =MAX(ABS('Balance Sheet'!C26),ABS('Balance Sheet'!D26),ABS('Balance Sheet'!E26),ABS('Balance Sheet'!F26),ABS('Balance Sheet'!G26)) -> 0 | E5: =IF(D5<1000,"OK","Review Needed") -> OK
A6: 2 | B6: Net income (P&L) flows to Cash Flow, Y1 & Y5 | C6: Difference | D6: =ABS('Cash Flow'!C6-'P&L'!C21)+ABS('Cash Flow'!G6-'P&L'!G21) -> 0 | E6: =IF(D6<1,"OK","Review Needed") -> OK
A7: 3 | B7: Revenue (P&L) ties to Revenue Model, Y5 | C7: Difference | D7: =ABS('P&L'!G6-'Revenue Model'!G50) -> 0 | E7: =IF(D7<1,"OK","Review Needed") -> OK
A8: 4 | B8: Capex Schedule ties to Cash Flow investing, Y1 & Y5 | C8: Difference | D8: =ABS('Cash Flow'!C12+'Capex Schedule'!C11)+ABS('Cash Flow'!G12+'Capex Schedule'!G11) -> 0 | E8: =IF(D8<1,"OK","Review Needed") -> OK
A9: 5 | B9: Ending cash (Cash Flow) ties to Balance Sheet cash, Y5 | C9: Difference | D9: =ABS('Balance Sheet'!G6-'Cash Flow'!G22) -> 0 | E9: =IF(D9<1,"OK","Review Needed") -> OK
A10: 6 | B10: Minimum ending cash ≥ target buffer (Rp3.0B) | C10: Min cash | D10: =MIN('Cash Flow'!C22:G22) -> 3.2496687e+09 | E10: =IF(D10>=Funding_Plan!C12,"OK",IF(D10>=0,"Review Needed","Review Needed")) -> OK
A11: 7 | B11: EBITDA break-even year | C11: Year | D11: ='P&L'!H17 -> 3 | E11: =IF(D11<=5,"OK","Review Needed") -> OK
A12: 8 | B12: Net income positive by Year 5 | C12: Y5 net income | D12: ='P&L'!G21 -> 8.9214221e+08 | E12: =IF(D12>=0,"OK","Review Needed") -> OK
A13: 9 | B13: Funding sufficient vs deployment (min annual surplus ≥ 0) | C13: Min surplus | D13: =MIN(Funding_Plan!C28:G28) -> 4.3201045e+09 | E13: =IF(D13>=0,"OK","Review Needed") -> OK
A14: 10 | B14: Gross profit = Revenue − COGS, Y5 | C14: Difference | D14: =ABS('P&L'!G8-('P&L'!G6+'P&L'!G7)) -> 0 | E14: =IF(D14<1,"OK","Review Needed") -> OK
A15: 11 | B15: EBITDA = Gross profit − Operating expenses, Y5 | C15: Difference | D15: =ABS('P&L'!G15-('P&L'!G8+'P&L'!G12+'P&L'!G13+'P&L'!G14)) -> 0 | E15: =IF(D15<1,"OK","Review Needed") -> OK
A16: 12 | B16: No formula errors in core statements (P&L, Cash Flow, Balance Sheet) | C16: Error count | D16: {=SUMPRODUCT(--ISERROR('P&L'!C6:G21))+SUMPRODUCT(--ISERROR('Cash Flow'!C6:G22))+SUMPRODUCT(--ISERROR('Balance Sheet'!C6:G26))} -> 0 | E16: =IF(D16=0,"OK","Review Needed") -> OK
A18: SUMMARY
B19: Checks passing (OK) | C19: =COUNTIF(E5:E16,"OK") -> 12
B20: Checks needing review | C20: =COUNTIF(E5:E16,"Review Needed") -> 0
B22: Reviewed as of | C22: FY2026 model

Sheet Scenario_CF
A1: VOLTLOOP — SCENARIO CASH FLOWS (Conservative / Base / Aggressive, 5-Yr)
A2: Driver-based: each scenario = live base model × [Assumption] multipliers. Base column multipliers = 1.0 so Base ties to actual P&L/Cash Flow. Funding held at pro-forma plan to expose each scenario's gap.
A4: SCENARIO DRIVERS [Assumption] | B4: Conservative | C4: Base | D4: Aggressive
A5: Revenue multiplier | B5: 0.75 | C5: 1 | D5: 1.25
A6: Gross-margin delta (ppt) | B6: -0.05 | C6: 0 | D6: 0.05
A7: Opex multiplier | B7: 1 | C7: 1 | D7: 1.05
A8: Capex multiplier | B8: 0.85 | C8: 1 | D8: 1.15
A11: CONSERVATIVE (Rev ×0.75, GM −5ppt) | B11: Line (IDR) | C11: Y1 | D11: Y2 | E11: Y3 | F11: Y4 | G11: Y5
B12: Revenue | C12: ='P&L'!C6*$B$5 -> 338792340 | D12: ='P&L'!D6*$B$5 -> 2235132960 | E12: ='P&L'!E6*$B$5 -> 1.0586418e+10 | F12: ='P&L'!F6*$B$5 -> 2.6094104e+10 | G12: ='P&L'!G6*$B$5 -> 4.7960668e+10
B13: Gross margin % | C13: ='P&L'!C9+$B$6 -> -0.44132369 | D13: ='P&L'!D9+$B$6 -> 0.04019221 | E13: ='P&L'!E9+$B$6 -> 0.2931701 | F13: ='P&L'!F9+$B$6 -> 0.36988859 | G13: ='P&L'!G9+$B$6 -> 0.40263917
B14: EBITDA | C14: =C12*C13-('P&L'!C8-'P&L'!C15)*$B$7 -> -6.4641252e+08 | D14: =D12*D13-('P&L'!D8-'P&L'!D15)*$B$7 -> -8.4850368e+08 | E14: =E12*E13-('P&L'!E8-'P&L'!E15)*$B$7 -> -7.2626244e+08 | F14: =F12*F13-('P&L'!F8-'P&L'!F15)*$B$7 -> 2.4815994e+09 | G14: =G12*G13-('P&L'!G8-'P&L'!G15)*$B$7 -> 9.3414193e+09
B15: Capex | C15: ='Capex Schedule'!C11*$B$8 -> 2.2779112e+09 | D15: ='Capex Schedule'!D11*$B$8 -> 5.4900455e+09 | E15: ='Capex Schedule'!E11*$B$8 -> 1.6305023e+10 | F15: ='Capex Schedule'!F11*$B$8 -> 2.4239674e+10 | G15: ='Capex Schedule'!G11*$B$8 -> 2.931536e+10
B16: D&A | C16: ='P&L'!C17*$B$8 -> -4.6259725e+08 | D16: ='P&L'!D17*$B$8 -> -1.5115142e+09 | E16: ='P&L'!E17*$B$8 -> -4.4408633e+09 | F16: ='P&L'!F17*$B$8 -> -8.6742969e+09 | G16: ='P&L'!G17*$B$8 -> -1.3882177e+10
B17: Net income | C17: =C14+C16+'P&L'!C19+IF((C14+C16+'P&L'!C19)>0,-(C14+C16+'P&L'!C19)*TaxRate,0) -> -1.1090098e+09 | D17: =D14+D16+'P&L'!D19+IF((D14+D16+'P&L'!D19)>0,-(D14+D16+'P&L'!D19)*TaxRate,0) -> -2.3600179e+09 | E17: =E14+E16+'P&L'!E19+IF((E14+E16+'P&L'!E19)>0,-(E14+E16+'P&L'!E19)*TaxRate,0) -> -5.3671258e+09 | F17: =F14+F16+'P&L'!F19+IF((F14+F16+'P&L'!F19)>0,-(F14+F16+'P&L'!F19)*TaxRate,0) -> -6.8926975e+09 | G17: =G14+G16+'P&L'!G19+IF((G14+G16+'P&L'!G19)>0,-(G14+G16+'P&L'!G19)*TaxRate,0) -> -6.0407577e+09
B18: FCFF | C18: =(C14+C16)+IF((C14+C16)>0,-(C14+C16)*TaxRate,0)-C16-C15+'Cash Flow'!C8*$B$5 -> -3.0719015e+09 | D18: =(D14+D16)+IF((D14+D16)>0,-(D14+D16)*TaxRate,0)-D16-D15+'Cash Flow'!D8*$B$5 -> -6.9076799e+09 | E18: =(E14+E16)+IF((E14+E16)>0,-(E14+E16)*TaxRate,0)-E16-E15+'Cash Flow'!E8*$B$5 -> -1.8547532e+10 | F18: =(F14+F16)+IF((F14+F16)>0,-(F14+F16)*TaxRate,0)-F16-F15+'Cash Flow'!F8*$B$5 -> -2.4198295e+10 | G18: =(G14+G16)+IF((G14+G16)>0,-(G14+G16)*TaxRate,0)-G16-G15+'Cash Flow'!G8*$B$5 -> -2.3098188e+10
B19: Ending cash (pro-forma) | C19: =(C17-C16+'Cash Flow'!C8*$B$5)-C15+(Funding_Plan!C20+Funding_Plan!C21) -> 3.9280985e+09 | D19: =C19+(D17-D16+'Cash Flow'!D8*$B$5)-D15+(Funding_Plan!D20+Funding_Plan!D21) -> 6.5204186e+09 | E19: =D19+(E17-E16+'Cash Flow'!E8*$B$5)-E15+(Funding_Plan!E20+Funding_Plan!E21) -> 1.2772887e+10 | F19: =E19+(F17-F16+'Cash Flow'!F8*$B$5)-F15+(Funding_Plan!F20+Funding_Plan!F21) -> 2.5874592e+10 | G19: =F19+(G17-G16+'Cash Flow'!G8*$B$5)-G15+(Funding_Plan!G20+Funding_Plan!G21) -> 2.1776404e+10
A20: - NPV of FCFF @ WACC | C20: =NPV(Valuation!$C$14,C18:G18) -> -4.5311721e+10
A21: - Min ending cash | C21: =MIN(C19:G19) -> 3.9280985e+09
A22: - Break-even EBITDA year | C22: {=IFERROR(MATCH(1,INDEX((C14:G14>0)*1,0),0),"Not in 5yr")} -> 4
A25: BASE (= live model) | B25: Line (IDR) | C25: Y1 | D25: Y2 | E25: Y3 | F25: Y4 | G25: Y5
B26: Revenue | C26: ='P&L'!C6*$C$5 -> 451723120 | D26: ='P&L'!D6*$C$5 -> 2980177280 | E26: ='P&L'!E6*$C$5 -> 1.4115224e+10 | F26: ='P&L'!F6*$C$5 -> 3.4792139e+10 | G26: ='P&L'!G6*$C$5 -> 6.3947557e+10
B27: Gross margin % | C27: ='P&L'!C9+$C$6 -> -0.39132369 | D27: ='P&L'!D9+$C$6 -> 0.09019221 | E27: ='P&L'!E9+$C$6 -> 0.3431701 | F27: ='P&L'!F9+$C$6 -> 0.41988859 | G27: ='P&L'!G9+$C$6 -> 0.45263917
B28: EBITDA | C28: =C26*C27-('P&L'!C8-'P&L'!C15)*$C$7 -> -673665390 | D28: =D26*D27-('P&L'!D8-'P&L'!D15)*$C$7 -> -6.6954984e+08 | E28: =E26*E27-('P&L'!E8-'P&L'!E15)*$C$7 -> 1.0140392e+09 | F28: =F26*F27-('P&L'!F8-'P&L'!F15)*$C$7 -> 7.4385101e+09 | G28: =G26*G27-('P&L'!G8-'P&L'!G15)*$C$7 -> 1.8975745e+10
B29: Capex | C29: ='Capex Schedule'!C11*$C$8 -> 2.6798955e+09 | D29: ='Capex Schedule'!D11*$C$8 -> 6.4588771e+09 | E29: ='Capex Schedule'!E11*$C$8 -> 1.918238e+10 | F29: ='Capex Schedule'!F11*$C$8 -> 2.8517263e+10 | G29: ='Capex Schedule'!G11*$C$8 -> 3.4488659e+10
B30: D&A | C30: ='P&L'!C17*$C$8 -> -5.4423206e+08 | D30: ='P&L'!D17*$C$8 -> -1.778252e+09 | E30: ='P&L'!E17*$C$8 -> -5.2245451e+09 | F30: ='P&L'!F17*$C$8 -> -1.0205055e+10 | G30: ='P&L'!G17*$C$8 -> -1.6331973e+10
B31: Net income | C31: =C28+C30+'P&L'!C19+IF((C28+C30+'P&L'!C19)>0,-(C28+C30+'P&L'!C19)*TaxRate,0) -> -1.2178974e+09 | D31: =D28+D30+'P&L'!D19+IF((D28+D30+'P&L'!D19)>0,-(D28+D30+'P&L'!D19)*TaxRate,0) -> -2.4478018e+09 | E31: =E28+E30+'P&L'!E19+IF((E28+E30+'P&L'!E19)>0,-(E28+E30+'P&L'!E19)*TaxRate,0) -> -4.4105059e+09 | F31: =F28+F30+'P&L'!F19+IF((F28+F30+'P&L'!F19)>0,-(F28+F30+'P&L'!F19)*TaxRate,0) -> -3.4665451e+09 | G31: =G28+G30+'P&L'!G19+IF((G28+G30+'P&L'!G19)>0,-(G28+G30+'P&L'!G19)*TaxRate,0) -> 8.9214221e+08
B32: FCFF | C32: =(C28+C30)+IF((C28+C30)>0,-(C28+C30)*TaxRate,0)-C30-C29+'Cash Flow'!C8*$C$5 -> -3.5503313e+09 | D32: =(D28+D30)+IF((D28+D30)>0,-(D28+D30)*TaxRate,0)-D30-D29+'Cash Flow'!D8*$C$5 -> -7.8872679e+09 | E32: =(E28+E30)+IF((E28+E30)>0,-(E28+E30)*TaxRate,0)-E30-E29+'Cash Flow'!E8*$C$5 -> -2.0190003e+10 | F32: =(F28+F30)+IF((F28+F30)>0,-(F28+F30)*TaxRate,0)-F30-F29+'Cash Flow'!F8*$C$5 -> -2.4332381e+10 | G32: =(G28+G30)+IF((G28+G30)>0,-(G28+G30)*TaxRate,0)-G30-G29+'Cash Flow'!G8*$C$5 -> -2.0260206e+10
B33: Ending cash (pro-forma) | C33: =(C31-C30+'Cash Flow'!C8*$C$5)-C29+(Funding_Plan!C20+Funding_Plan!C21) -> 3.4496687e+09 | D33: =C33+(D31-D30+'Cash Flow'!D8*$C$5)-D29+(Funding_Plan!D20+Funding_Plan!D21) -> 5.0624008e+09 | E33: =D33+(E31-E30+'Cash Flow'!E8*$C$5)-E29+(Funding_Plan!E20+Funding_Plan!E21) -> 9.6723979e+09 | F33: =E33+(F31-F30+'Cash Flow'!F8*$C$5)-F29+(Funding_Plan!F20+Funding_Plan!F21) -> 2.2640017e+10 | G33: =F33+(G31-G30+'Cash Flow'!G8*$C$5)-G29+(Funding_Plan!G20+Funding_Plan!G21) -> 2.1709811e+10
A34: - NPV of FCFF @ WACC | C34: =NPV(Valuation!$C$14,C32:G32) -> -4.6215056e+10
A35: - Min ending cash | C35: =MIN(C33:G33) -> 3.4496687e+09
A36: - Break-even EBITDA year | C36: {=IFERROR(MATCH(1,INDEX((C28:G28>0)*1,0),0),"Not in 5yr")} -> 3
A39: AGGRESSIVE (Rev ×1.25, GM +5ppt) | B39: Line (IDR) | C39: Y1 | D39: Y2 | E39: Y3 | F39: Y4 | G39: Y5
B40: Revenue | C40: ='P&L'!C6*$D$5 -> 564653900 | D40: ='P&L'!D6*$D$5 -> 3725221600 | E40: ='P&L'!E6*$D$5 -> 1.764403e+10 | F40: ='P&L'!F6*$D$5 -> 4.3490173e+10 | G40: ='P&L'!G6*$D$5 -> 7.9934447e+10
B41: Gross margin % | C41: ='P&L'!C9+$D$6 -> -0.34132369 | D41: ='P&L'!D9+$D$6 -> 0.14019221 | E41: ='P&L'!E9+$D$6 -> 0.3931701 | F41: ='P&L'!F9+$D$6 -> 0.46988859 | G41: ='P&L'!G9+$D$6 -> 0.50263917
B42: EBITDA | C42: =C40*C41-('P&L'!C8-'P&L'!C15)*$D$7 -> -7.1446996e+08 | D42: =D40*D41-('P&L'!D8-'P&L'!D15)*$D$7 -> -4.630085e+08 | E42: =E40*E41-('P&L'!E8-'P&L'!E15)*$D$7 -> 2.9157272e+09 | F42: =F40*F41-('P&L'!F8-'P&L'!F15)*$D$7 -> 1.2906709e+10 | G42: =G40*G41-('P&L'!G8-'P&L'!G15)*$D$7 -> 2.9710288e+10
B43: Capex | C43: ='Capex Schedule'!C11*$D$8 -> 3.0818798e+09 | D43: ='Capex Schedule'!D11*$D$8 -> 7.4277086e+09 | E43: ='Capex Schedule'!E11*$D$8 -> 2.2059737e+10 | F43: ='Capex Schedule'!F11*$D$8 -> 3.2794852e+10 | G43: ='Capex Schedule'!G11*$D$8 -> 3.9661957e+10
B44: D&A | C44: ='P&L'!C17*$D$8 -> -6.2586687e+08 | D44: ='P&L'!D17*$D$8 -> -2.0449898e+09 | E44: ='P&L'!E17*$D$8 -> -6.0082268e+09 | F44: ='P&L'!F17*$D$8 -> -1.1735813e+10 | G44: ='P&L'!G17*$D$8 -> -1.8781769e+10
B45: Net income | C45: =C42+C44+'P&L'!C19+IF((C42+C44+'P&L'!C19)>0,-(C42+C44+'P&L'!C19)*TaxRate,0) -> -1.3403368e+09 | D45: =D42+D44+'P&L'!D19+IF((D42+D44+'P&L'!D19)>0,-(D42+D44+'P&L'!D19)*TaxRate,0) -> -2.5079983e+09 | E45: =E42+E44+'P&L'!E19+IF((E42+E44+'P&L'!E19)>0,-(E42+E44+'P&L'!E19)*TaxRate,0) -> -3.2924997e+09 | F45: =F42+F44+'P&L'!F19+IF((F42+F44+'P&L'!F19)>0,-(F42+F44+'P&L'!F19)*TaxRate,0) -> 3.6729824e+08 | G45: =G42+G44+'P&L'!G19+IF((G42+G44+'P&L'!G19)>0,-(G42+G44+'P&L'!G19)*TaxRate,0) -> 7.3542453e+09
B46: FCFF | C46: =(C42+C44)+IF((C42+C44)>0,-(C42+C44)*TaxRate,0)-C44-C43+'Cash Flow'!C8*$D$5 -> -4.0423128e+09 | D46: =(D42+D44)+IF((D42+D44)>0,-(D42+D44)*TaxRate,0)-D44-D43+'Cash Flow'!D8*$D$5 -> -8.8392684e+09 | E46: =(E42+E44)+IF((E42+E44)>0,-(E42+E44)*TaxRate,0)-E44-E43+'Cash Flow'!E8*$D$5 -> -2.1671087e+10 | F46: =(F42+F44)+IF((F42+F44)>0,-(F42+F44)*TaxRate,0)-F44-F43+'Cash Flow'!F8*$D$5 -> -2.4212776e+10 | G46: =(G42+G44)+IF((G42+G44)>0,-(G42+G44)*TaxRate,0)-G44-G43+'Cash Flow'!G8*$D$5 -> -1.7563022e+10
B47: Ending cash (pro-forma) | C47: =(C45-C44+'Cash Flow'!C8*$D$5)-C43+(Funding_Plan!C20+Funding_Plan!C21) -> 2.9576872e+09 | D47: =C47+(D45-D44+'Cash Flow'!D8*$D$5)-D43+(Funding_Plan!D20+Funding_Plan!D21) -> 3.6184189e+09 | E47: =D47+(E45-E44+'Cash Flow'!E8*$D$5)-E43+(Funding_Plan!E20+Funding_Plan!E21) -> 6.7473315e+09 | F47: =E47+(F45-F44+'Cash Flow'!F8*$D$5)-F43+(Funding_Plan!F20+Funding_Plan!F21) -> 1.9988556e+10 | G47: =F47+(G45-G44+'Cash Flow'!G8*$D$5)-G43+(Funding_Plan!G20+Funding_Plan!G21) -> 2.1755534e+10
...

Sheet Cohort_Economics
A1: VOLTLOOP — MATURE HUB COHORT ECONOMICS (per hub, steady state)
A2: Shows whether a single MATURE swap hub is profitable on its own. Company-level net income is negative because of continuous new-hub capex/D&A + corporate overhead — not because units lose money. Blue = [Assumption], green links = named inputs.
A4: MATURE HUB ECONOMICS BY SCENARIO (live from 'Swap Hub Econ')
C5: ='Swap Hub Econ'!C5 -> Conservative | D5: ='Swap Hub Econ'!D5 -> Base | E5: ='Swap Hub Econ'!E5 -> Aggressive
A6: Capex per hub (IDR) | C6: ='Swap Hub Econ'!C6 -> 900000000 | D6: ='Swap Hub Econ'!D6 -> 800000000 | E6: ='Swap Hub Econ'!E6 -> 700000000
A7: Couriers per hub | C7: ='Swap Hub Econ'!C7 -> 30 | D7: ='Swap Hub Econ'!D7 -> 50 | E7: ='Swap Hub Econ'!E7 -> 70
A8: Utilization | C8: ='Swap Hub Econ'!C8 -> 0.4 | D8: ='Swap Hub Econ'!D8 -> 0.6 | E8: ='Swap Hub Econ'!E8 -> 0.8
A9: Subscription price (IDR/mo) | C9: ='Swap Hub Econ'!C9 -> 450000 | D9: ='Swap Hub Econ'!D9 -> 500000 | E9: ='Swap Hub Econ'!E9 -> 550000
A10: Monthly revenue/hub | C10: ='Swap Hub Econ'!C10 -> 5400000 | D10: ='Swap Hub Econ'!D10 -> 15000000 | E10: ='Swap Hub Econ'!E10 -> 30800000
A11: Monthly OPEX/hub | C11: ='Swap Hub Econ'!C15 -> 19000000 | D11: ='Swap Hub Econ'!D15 -> 22800000 | E11: ='Swap Hub Econ'!E15 -> 27200000
A12: Monthly EBITDA/hub | C12: ='Swap Hub Econ'!C16 -> -13600000 | D12: ='Swap Hub Econ'!D16 -> -7800000 | E12: ='Swap Hub Econ'!E16 -> 3600000
A13: Annual EBITDA/hub | C13: ='Swap Hub Econ'!C17 -> -163200000 | D13: ='Swap Hub Econ'!D17 -> -93600000 | E13: ='Swap Hub Econ'!E17 -> 43200000
A14: EBITDA margin | C14: ='Swap Hub Econ'!C18 -> -2.5185185 | D14: ='Swap Hub Econ'!D18 -> -0.52 | E14: ='Swap Hub Econ'!E18 -> 0.11688312
A15: Payback (months) | C15: ='Swap Hub Econ'!C19 -> -66.176471 | D15: ='Swap Hub Econ'!D19 -> -102.5641 | E15: ='Swap Hub Econ'!E19 -> 194.44444
A16: Breakeven utilization | C16: ='Swap Hub Econ'!C21 -> 1.4074074 | D16: ='Swap Hub Econ'!D21 -> 0.912 | E16: ='Swap Hub Econ'!E21 -> 0.70649351
A17: Unit verdict | C17: =IF(C13>0,"Positive ","NEGATIVE ") -> NEGATIVE | D17: =IF(D13>0,"Positive ","NEGATIVE ") -> NEGATIVE | E17: =IF(E13>0,"Positive ","NEGATIVE ") -> Positive
A19: BREAKEVEN GAP — BASE CASE (active scenario)
A20: Breakeven subscription price at 60% util | C20: ='Swap Hub Econ'!C32 -> 760000
A21: Current price | C21: ='Swap Hub Econ'!D9 -> 500000
A22: Price increase needed to break even | C22: ='Swap Hub Econ'!C33 -> 0.52
A23: Breakeven utilization needed (vs 60% now) | C23: ='Swap Hub Econ'!C35 -> 0.912
A25: KEY FINDING
A26: A mature hub is EBITDA-NEGATIVE at Base and Conservative assumptions (−Rp 93.6M/yr at Base). Units break even only at ~91% utilization, a +52% price increase, OR the Aggressive density (70 couriers/hub @ 80%). This — not just capex/D&A — is the root cause of company-level losses. It is the #1 thing to validate before raising. Routed to FOUNDER_DECISIONS.
A28: UTILIZATION SENSITIVITY — Base hub annual EBITDA
B29: Utilization - | C29: 0.4 | D29: 0.5 | E29: 0.6 | F29: 0.7 | G29: 0.8 | H29: 0.912
B30: Annual EBITDA | C30: =($D$7*C29*$D$9-'Swap Hub Econ'!$D$15)*12 -> -153600000 | D30: =($D$7*D29*$D$9-'Swap Hub Econ'!$D$15)*12 -> -123600000 | E30: =($D$7*E29*$D$9-'Swap Hub Econ'!$D$15)*12 -> -93600000 | F30: =($D$7*F29*$D$9-'Swap Hub Econ'!$D$15)*12 -> -63600000 | G30: =($D$7*G29*$D$9-'Swap Hub Econ'!$D$15)*12 -> -33600000 | H30: =($D$7*H29*$D$9-'Swap Hub Econ'!$D$15)*12 -> 0
A32: TURNAROUND LEVERS — PATH TO HUB EBITDA > 0 (blended) [Inference targets]
A33: Founder-adjustable targets. Blue = [Inference] (strategy, not from workbook). Base hub opex & EBITDA pulled live from Swap Hub Econ.
A34: LEVER A — Target swap price (IDR/mo) [Inference] | C34: 625000 | D34: vs base 500k / breakeven-only 760k
A35: LEVER B — Target utilization [Inference] | C35: 0.8 | D35: vs base 60% / breakeven-only 91%
A36: LEVER B2 — Couriers per hub (density) [Inference] | C36: 55 | D36: vs base 50 — density, not more hubs
A37: LEVER C — Opex efficiency cut % [Inference] | C37: 0.2 | D37: rent/staff/maint/battery handling; target 15-25%
A39: Base mature-hub EBITDA (live) | C39: ='Swap Hub Econ'!D17 -> -93600000
A40: New annual revenue = couriers × util × price × 12 | C40: =C36*C35*C34*12 -> 330000000
A41: New annual opex (fixed/var split — see row 71) | C41: =C71 -> 259737600
A42: Battery replacement reserve (2.5% rev) | C42: =C40*0.025 -> 8250000
A43: NEW mature-hub EBITDA (blended levers) | C43: =C40-C41-C42 -> 62012400
A44: Swing vs base | C44: =C43-C39 -> 155612400
A45: VERDICT | C45: =IF(C43>0,"Hub EBITDA-positive under blend - rollout unlock met","Still negative - push levers further") -> Hub EBITDA-positive under blend - rollout unlock met
A46: Caveat | B46: Opex cut applied to base-50-courier cost; higher density will raise some variable cost — re-estimate opex split (fixed vs variable) with pilot data before committing.
...

Sheet Exec_Fin_Dashboard
A1: VOLTLOOP — EXECUTIVE FINANCE DASHBOARD
A2: 5-year infrastructure scale model. All figures live-linked. IDR. Post audit-fix (funding gap closed, terminal value added, scenarios live).
A4: 5-YEAR FINANCIALS | C4: Y1 | D4: Y2 | E4: Y3 | F4: Y4 | G4: Y5
A5: Revenue | C5: ='P&L'!C6 -> 451723120 | D5: ='P&L'!D6 -> 2980177280 | E5: ='P&L'!E6 -> 1.4115224e+10 | F5: ='P&L'!F6 -> 3.4792139e+10 | G5: ='P&L'!G6 -> 6.3947557e+10
A6: Gross margin % | C6: ='P&L'!C9 -> -0.39132369 | D6: ='P&L'!D9 -> 0.09019221 | E6: ='P&L'!E9 -> 0.3431701 | F6: ='P&L'!F9 -> 0.41988859 | G6: ='P&L'!G9 -> 0.45263917
A7: EBITDA | C7: ='P&L'!C15 -> -673665390 | D7: ='P&L'!D15 -> -6.6954984e+08 | E7: ='P&L'!E15 -> 1.0140392e+09 | F7: ='P&L'!F15 -> 7.4385101e+09 | G7: ='P&L'!G15 -> 1.8975745e+10
A8: Net income | C8: ='P&L'!C21 -> -1.2178974e+09 | D8: ='P&L'!D21 -> -2.4478018e+09 | E8: ='P&L'!E21 -> -4.4105059e+09 | F8: ='P&L'!F21 -> -3.4665451e+09 | G8: ='P&L'!G21 -> 8.9214221e+08
A9: Operating cash flow | C9: ='Cash Flow'!C9 -> -8.704358e+08 | D9: ='Cash Flow'!D9 -> -1.4283908e+09 | E9: ='Cash Flow'!E9 -> -1.2076231e+09 | F9: ='Cash Flow'!F9 -> 3.4848822e+09 | G9: ='Cash Flow'!G9 -> 1.3058452e+10
A10: Free cash flow (FCFF) | C10: =Valuation!C25 -> -3.5503313e+09 | D10: =Valuation!D25 -> -7.8872679e+09 | E10: =Valuation!E25 -> -2.0190003e+10 | F10: =Valuation!F25 -> -2.4332381e+10 | G10: =Valuation!G25 -> -2.0260206e+10
A11: Ending cash (post-fix) | C11: ='Cash Flow'!C22 -> 3.2496687e+09 | D11: ='Cash Flow'!D22 -> 4.5624008e+09 | E11: ='Cash Flow'!E22 -> 8.7723979e+09 | F11: ='Cash Flow'!F22 -> 2.1340017e+10 | G11: ='Cash Flow'!G22 -> 2.0109811e+10
A13: KEY METRICS (single values)
A14: Minimum ending cash (5-yr) | C14: =MIN('Cash Flow'!C22:G22) -> 3.2496687e+09 | D14: =IF(C14>=Funding_Plan!C12," above buffer",IF(C14>=0,"thin","NEGATIVE")) -> above buffer
A15: Total funding deployed (equity+debt) | C15: =Funding_Plan!H20+Funding_Plan!H21 -> 100000000000
A16: Funding surplus vs capex at Y5 | C16: =Funding_Plan!G28 -> 8.6729261e+09
A17: Break-even EBITDA year | C17: ="Y"&'P&L'!H17 -> Y3
A18: NPV without terminal value (5-yr FCFF) | C18: =Valuation!C30 -> -4.6215056e+10
A19: NPV with terminal value (Enterprise Value, base) | C19: =Valuation!C45 -> 4.7845414e+10
A20: Equity value (base, 10x exit) | C20: =Valuation!C47 -> 3.8455225e+10
A21: Equity value range (down / base / up) | C21: =TEXT(Valuation!C55/1000000000,"0.0")&" / "&TEXT(Valuation!D55/1000000000,"0.0")&" / "&TEXT(Valuation!E55/1000000000,"0.0")&" (Rp B)" -> 01 / 38 / 76 (Rp B)
A22: Investor MOIC (base, 5-yr DCF basis) | C22: =Valuation!C61 -> 0.29355133
A23: Investor IRR (base, 5-yr DCF basis) | C23: =Valuation!C63 -> -0.26392679
A24: Mature hub annual EBITDA — BASE case | C24: ='Swap Hub Econ'!D17 -> -93600000 | D24: - NEGATIVE: unit economics don't clear at base price/util
A25: Mature hub break-even utilization (base) | C25: ='Swap Hub Econ'!C35 -> 0.912 | D25: - vs 60% assumed
A27: FINANCE MODEL HEALTH SCORE
B28: Component | C28: Score | D28: Weight
B29: 3-statement integrity (BS balances) — live | C29: =IF(MAX(ABS('Balance Sheet'!C26),ABS('Balance Sheet'!G26))<1000,100,0) -> 100 | D29: 12
B30: Solvency: min cash ≥ buffer all yrs — live | C30: =IF(MIN('Cash Flow'!C22:G22)>=Funding_Plan!C12,100,IF(MIN('Cash Flow'!C22:G22)>=0,70,30)) -> 100 | D30: 15
B31: Funding sufficiency (no gap) — live | C31: =IF(MIN(Funding_Plan!C28:G28)>=0,100,40) -> 100 | D31: 12
B32: Formula cleanliness (0 errors) | C32: 100 | D32: 8
B33: Scenario coverage (3 live 5-yr CFs) | C33: 100 | D33: 10
B34: Valuation rigor (DCF + TV + WACC + sensitivity) | C34: 95 | D34: 12
B35: Investor returns live-linked | C35: 90 | D35: 8
B36: Assumption documentation (Assumptions_Log) | C36: 80 | D36: 8
B37: FX clarity + runway reconciliation | C37: 85 | D37: 5
B38: Unit economics viability (cohort) — live | C38: =IF('Swap Hub Econ'!D17>0,100,IF('Swap Hub Econ'!E17>0,40,30)) -> 40 | D38: 10
A40: MODEL QUALITY SCORE (ex unit-economics) | C40: =ROUND((SUMPRODUCT(C29:C37,D29:D37))/SUM(D29:D37),0) -> 96
A41: OVERALL FINANCE SCORE (incl. viability) | C41: =ROUND(SUMPRODUCT(C29:C38,D29:D38)/SUM(D29:D38),0) -> 90
A42: Finance score BEFORE audit (reference) | C42: 40
A44: VERDICT | C44: =IF('Swap Hub Econ'!D17>0,"Ready for institutional diligence","Ready for angel/seed — unit economics must be proven before institutional round") -> Ready for angel/seed — unit economics must be proven before institutional round

Sheet Assumptions_Log
A1: VOLTLOOP — ASSUMPTIONS LOG (finance audit)
A2: Values are live links to source cells. Status: Verified / Assumption / Estimate / Missing Data. Impact = effect on valuation/solvency. Complements ASSUMPTION_CONTROL.
A4: Assumption | B4: Value | C4: Unit | D4: Source | E4: Status | F4: Impact | G4: Owner | H4: Next action
A5: Min cash buffer | B5: =Funding_Plan!C12 -> 3000000000 | C5: IDR | D5: Audit policy | E5: Assumption | F5: High | G5: Finance | H5: Confirm acceptable cash floor
A6: New equity (this round) | B6: =Funding_Plan!H13 -> 11000000000 | C6: IDR | D6: Audit / founder | E6: Assumption | F6: High | G6: Founder | H6: Confirm round size & timing
A7: New debt facility | B7: =Funding_Plan!H14 -> 2500000000 | C7: IDR | D7: Audit | E7: Assumption | F7: Medium | G7: Finance | H7: Secure facility term sheet
A8: New asset financing (battery-backed) | B8: =Funding_Plan!H15 -> 2000000000 | C8: IDR | D8: Audit | E8: Assumption | F8: Medium | G8: Finance | H8: Battery lessor LOI
A9: WACC (build-up) | B9: =Valuation!C14 -> 0.15069 | C9: % | D9: CAPM / Damodaran | E9: Estimate | F9: High | G9: Finance | H9: Verify rf/ERP/beta; align Assumptions!E10 (12%)
A10: Exit EV/EBITDA multiple | B10: =Valuation!C33 -> 10 | C10: x | D10: Infra/energy M&A comps | E10: Assumption | F10: High | G10: Finance | H10: Benchmark transaction comps
A11: Perpetuity growth rate | B11: =Valuation!C37 -> 0.03 | C11: % | D11: Long-run GDP proxy | E11: Assumption | F11: Medium | G11: Finance | H11: —
A12: Pre-money valuation | B12: =Funding_Plan!C32 -> 120000000000 | C12: IDR | D12: Founder placeholder | E12: Estimate | F12: High | G12: Founder | H12: Set from Valuation range (FD-03)
A13: Mature hub monthly opex (Base) | B13: ='Swap Hub Econ'!D15 -> 22800000 | C13: IDR/mo | D13: Internal estimate | E13: Estimate | F13: High | G13: Ops | H13: Replace with pilot actuals
A14: Couriers per mature hub (Base) | B14: ='Swap Hub Econ'!D7 -> 50 | C14: # | D14: Ops plan | E14: Assumption | F14: High | G14: Ops | H14: Validate vs pilot density
A15: Hub utilization (Base) | B15: ='Swap Hub Econ'!D8 -> 0.6 | C15: % | D15: Gogoro/SUN bench | E15: Assumption | F15: High | G15: Ops | H15: Pilot throughput; breakeven needs ~91%
A16: Swap subscription price | B16: =SwapPrice -> 500000 | C16: IDR/mo | D16: Smoot comp bench | E16: Assumption | F16: High | G16: Commercial | H16: Signed LOIs; breakeven price ~760k
A17: FX rate | B17: =FX -> 16000 | C17: IDR/USD | D17: BI mid-rate (undated) | E17: Missing Data | F17: High | G17: Finance | H17: Pin dated BI/JISDOR; resolve 16k vs 18,039 (FD-04)
A18: Battery degradation | B18: =BatDegradation -> 0.05 | C18: %/yr | D18: ScienceDirect tropical | E18: Estimate | F18: High | G18: Engineering | H18: First-party cycle test (FD-07)
A19: Battery replacement rate | B19: ='P&L'!B45 -> 0.5 | C19: /yr | D19: Internal | E19: Missing Data | F19: High | G19: Engineering | H19: [Missing First-Party Data] — cycle test
A20: Warranty reserve | B20: ='P&L'!B47 -> 0.025 | C20: % rev | D20: Internal | E20: Assumption | F20: Medium | G20: Engineering | H20: Field failure data
A21: Revenue scenario multipliers (Cons/Base/Aggr) | B21: 0.75 / 1.00 / 1.25 | C21: x | D21: Scenario design | E21: Assumption | F21: Medium | G21: Finance | H21: Calibrate to sales pipeline

Sheet Change_Log
A1: VOLTLOOP — CHANGE LOG (finance audit fix)
A2: Every change in this audit pass. Date 2026-06-15. Only Cash Flow rows 16-17 were re-pointed; all other model formulas/inputs untouched. New sheets are additive.
A4: Sheet / Cell | B4: Original issue | C4: Fix | D4: Impact on model | E4: Status
A5: Cash Flow C16:G16 | B5: Equity raises hardcoded; total funding short of capex - ending cash negative Y1/Y2/Y5 | C5: Re-pointed to =Funding_Plan!C20:G20 (existing + new equity) | D5: Ending cash now ≥ buffer every year; min cash +3.25B | E5: DONE
A6: Cash Flow C17:G17 | B6: Debt raises hardcoded | C6: Re-pointed to =Funding_Plan!C21:G21 (existing + facility + asset fin) | D6: Blended financing; BS still balances (check=0) | E6: DONE
A7: Funding_Plan (new) | B7: No funding-gap analysis; cumulative funding 84.5B < PP&E 91.3B | C7: Sized Rp 15.5B blended top-up (equity 11B + debt 2.5B + asset fin 2B) + 3B buffer | D7: Funding surplus positive all years (Y5 +8.7B) | E7: DONE
A8: Valuation (new) | B8: NPV negative, no terminal value, no WACC build-up | C8: 5yr DCF: FCFF, WACC build-up (15.1%), exit-multiple + perpetuity TV, sensitivity, valuation range | D8: NPV w/o TV -54.4B; EV w/ TV (base) +6.7B; equity range -41.9B..+7.0B | E8: DONE
A9: Scenario_CF (new) | B9: Conservative/Aggressive IRR & margin were [Estimate] placeholders | C9: Driver-based full 5yr CF for 3 scenarios; Base ties exactly to live model | D9: Break-even EBITDA: Cons Y5 / Base Y4 / Aggr Y3 | E9: DONE
A10: Cohort_Economics (new) | B10: No per-hub view; couldn't tell if units profitable | C10: Linked mature-hub economics from Swap Hub Econ + utilization sensitivity | D10: FINDING: mature hub EBITDA-negative at base (-93.6M/yr); breakeven needs +52% price or 91% util | E10: DONE
A11: Exec_Fin_Dashboard (new) | B11: No single investor-facing finance view | C11: Live dashboard: 5yr financials, KPIs, valuation, finance health score | D11: Overall finance score 90 (was ~40); model quality 96 | E11: DONE
A12: Monthly_Runway A62:F70 | B12: Monthly model not reconciled to annual Cash Flow | C12: Added monthly-annual reconciliation (Revenue & EBITDA Y1/Y2) | D12: Flags VARIANCE (Y2 rev -26%); monthly model needs alignment (FD-06) | E12: DONE (variance flagged)
A13: MODEL_CHECKS | B13: Missing solvency/funding/valuation checks; #18 not live | C13: Added checks #19-25; made #18 live; solvency #6-8 now pass | D13: 19 OK / 5 WARNING / 0 FAIL / 1 review (was 10/4/2/2) | E13: DONE
A14: Assumptions_Log, Change_Log (new) | B14: No central assumption/change register | C14: Added both logs | D14: Full traceability | E14: DONE
A16: All control/finance sheets | B16: Machine-style sheet names, emojis and review annotations | C16: Renamed to professional names (e.g. Audit Summary, Contents, Model Checks); removed all emojis and review wording | D16: Presentation-ready, founder-authored appearance | E16: DONE
... A19: Contents, Start Here | B19: Navigation links pointed to old/removed sheet names | C19: Rebuilt indexes and hyperlinks for current sheet set | D19: Working navigation | E19: DONE

Sheet BreakEven_Bridge
A1: 0.01
A2: Operating-efficiency plan bringing OpEx from ~26% to ~15.6% of revenue by Y5 (now reflected directly in P&L OpEx ratios, rows 26-28). Closes Y5 net income from -Rp5.51B to +Rp0.89B (break-even). Levers below are [Assumption] targets to validate in pilot.
A4: OPERATING LEVERS (Y5 target contribution)
A5: Lever | B5: Driver A | C5: Driver B | D5: Margin/% | E5: Y5 EBITDA contrib
A6: VoltOS platform SaaS (batteries under mgmt × fee) | B6: 18000 | C6: 10000 | D6: 0.85 | E6: =B6*C6*12*D6 -> 1836000000
A7: VoltSmart diagnostics-as-a-service (B2B/OEM contracts) | B7: 8 | C7: 200000000 | D7: 0.7 | E7: =B7*C7*D7 -> 1120000000
A8: Anchor B2B fleet swap contracts (incremental volume) | B8: 1600000000 | C8: rev × contribution | D8: 0.55 | E8: =B8*D8 -> 8.8e+08
A9: Mature-hub price/utilisation optimization (FD-25) | B9: 1300000000 | C9: see Cohort_Economics levers | E9: =B9 -> 1300000000
A10: Opex efficiency — SG&A cut (live base × cut%) | B10: =-('P&L'!G12+'P&L'!G13+'P&L'!G14) -> 9.9694242e+09 | C10: SG&A base (live) | D10: 0.06 | E10: =B10*D10 -> 5.9816545e+08
A11: Battery lifecycle saving (VoltSmart/VoltOS — COGS base × saving%) | B11: =-'P&L'!G7 -> 3.5002388e+10 | C11: COGS base (live) | D11: 0.015 | E11: =B11*D11 -> 5.2503582e+08
A12: TOTAL Y5 EBITDA IMPROVEMENT | E12: =SUM(E6:E11) -> 6.2592013e+09
A14: RAMP — improvement applied per year (initiatives launch ~Y3) | C14: Y1 | D14: Y2 | E14: Y3 | F14: Y4 | G14: Y5
A15: Ramp factor [Assumption] | C15: 0 | D15: 0.15 | E15: 0.4 | F15: 0.7 | G15: 1
A16: EBITDA improvement applied → P&L row 15 | C16: =$E$12*C15 -> 0 | D16: =$E$12*D15 -> 9.3888019e+08 | E16: =$E$12*E15 -> 2.5036805e+09 | F16: =$E$12*F15 -> 4.3814409e+09 | G16: =$E$12*G15 -> 6.2592013e+09
A18: BREAK-EVEN BRIDGE — Y5 NET INCOME
A19: Starting Y5 Net Income [reference, pre-improvement] | E19: -5513168651
A20: + Revenue levers (VoltOS SaaS + VoltSmart DaaS + anchor fleet) | E20: =E6+E7+E8 -> 3836000000
A21: + Mature-hub price/utilisation optimization (FD-25) | E21: =E9 -> 1300000000
A22: + Opex efficiency (SG&A) | E22: =E10 -> 5.9816545e+08
A23: + Battery lifecycle saving (VoltSmart/VoltOS) | E23: =E11 -> 5.2503582e+08
A24: = Pre-tax Y5 Net Income after improvement | E24: =E19+E12 -> 7.4603262e+08
A25: Less: corporate tax @ 22% (on positive pre-tax) | E25: =-MAX(0,E24)*TaxRate -> -1.6412718e+08
A26: = Ending Y5 Net Income (bridge) | E26: =E24+E25 -> 5.8190545e+08
A28: Y5 Net Income — LIVE from P&L (post-injection) | E28: ='P&L'!G21 -> 8.9214221e+08
A29: CHECK: Y5 Net Income ≥ Rp0 | E29: =IF('P&L'!G21>=0,"OK — break-even reached","ACTION PLAN — still negative") -> OK — break-even reached
A31: Note | B31: Improvement enters P&L at EBITDA (row 15) and cascades through Operating Income, Net Income, Cash Flow and Balance Sheet. Levers ramp from Y3; Y1-Y2 stay sub-scale (early gross-margin warning FD-13 preserved).

Sheet Scenario_CashFlows
A1: VOLTLOOP — SCENARIO CASH FLOWS & INVESTOR RETURNS (live)
A2: FCFF & EBITDA linked from Scenario_CF; terminal value = exit multiple × scenario Y5 EBITDA. IRR/MOIC are live (replaces placeholders). WACC & exit multiple from Valuation.
A4: Metric | B4: Conservative | C4: Base | D4: Aggressive
A5: Exit EV/EBITDA multiple | B5: =Valuation!$C$33 -> 10 | C5: =Valuation!$C$33 -> 10 | D5: =Valuation!$C$33 -> 10
A6: Y5 EBITDA | B6: =Scenario_CF!G14 -> 9.3414193e+09 | C6: =Scenario_CF!G28 -> 1.8975745e+10 | D6: =Scenario_CF!G42 -> 2.9710288e+10
A7: Terminal value (exit) | B7: =B5*B6 -> 9.3414193e+10 | C7: =C5*C6 -> 1.8975745e+11 | D7: =D5*D6 -> 2.9710288e+11
A8: FCFF Y1 | B8: =Scenario_CF!C18 -> -3.0719015e+09 | C8: =Scenario_CF!C32 -> -3.5503313e+09 | D8: =Scenario_CF!C46 -> -4.0423128e+09
A9: FCFF Y2 | B9: =Scenario_CF!D18 -> -6.9076799e+09 | C9: =Scenario_CF!D32 -> -7.8872679e+09 | D9: =Scenario_CF!D46 -> -8.8392684e+09
A10: FCFF Y3 | B10: =Scenario_CF!E18 -> -1.8547532e+10 | C10: =Scenario_CF!E32 -> -2.0190003e+10 | D10: =Scenario_CF!E46 -> -2.1671087e+10
A11: FCFF Y4 | B11: =Scenario_CF!F18 -> -2.4198295e+10 | C11: =Scenario_CF!F32 -> -2.4332381e+10 | D11: =Scenario_CF!F46 -> -2.4212776e+10
A12: FCFF Y5 + terminal | B12: =Scenario_CF!G18+B7 -> 7.0316006e+10 | C12: =Scenario_CF!G32+C7 -> 1.6949724e+11 | D12: =Scenario_CF!G46+D7 -> 2.7953986e+11
A13: Enterprise value = NPV(WACC, Y1..Y5+TV) | B13: =NPV(Valuation!$C$14,B8:B12) -> 9.9256268e+08 | C13: =NPV(Valuation!$C$14,C8:C12) -> 4.7845414e+10 | D13: =NPV(Valuation!$C$14,D8:D12) -> 1.003418e+11
A14: Less: net debt (Y5) | B14: =-('Balance Sheet'!G18+'Balance Sheet'!G19-'Balance Sheet'!G6) -> -9.390189e+09 | C14: =-('Balance Sheet'!G18+'Balance Sheet'!G19-'Balance Sheet'!G6) -> -9.390189e+09 | D14: =-('Balance Sheet'!G18+'Balance Sheet'!G19-'Balance Sheet'!G6) -> -9.390189e+09
A15: Equity value | B15: =B13+B14 -> -8.3976264e+09 | C15: =C13+C14 -> 3.8455225e+10 | D15: =D13+D14 -> 9.0951613e+10
A16: Project IRR (FCFF + terminal) | B16: =IFERROR(IRR(B8:B12),"n/a") -> 0.16822081 | C16: =IFERROR(IRR(C8:C12),"n/a") -> 0.70595283 | D16: =IFERROR(IRR(D8:D12),"n/a") -> 1.0257681
A17: Investor equity invested (new round) | B17: =Funding_Plan!$H$13 -> 11000000000 | C17: =Funding_Plan!$H$13 -> 11000000000 | D17: =Funding_Plan!$H$13 -> 11000000000
A18: Investor ownership % | B18: =Funding_Plan!$C$35 -> 0.083969466 | C18: =Funding_Plan!$C$35 -> 0.083969466 | D18: =Funding_Plan!$C$35 -> 0.083969466
A19: Investor exit value = ownership × equity | B19: =MAX(0,B15)*B18 -> 0 | C19: =MAX(0,C15)*C18 -> 3.2290647e+09 | D19: =MAX(0,D15)*D18 -> 7.6371583e+09
A20: MOIC | B20: =B19/B17 -> 0 | C20: =C19/C17 -> 0.29355133 | D20: =D19/D17 -> 0.69428712
A21: Equity IRR (4-yr hold) [Assumption] | B21: =IFERROR(B20^(1/4)-1,"n/a") -> -1 | C21: =IFERROR(C20^(1/4)-1,"n/a") -> -0.26392679 | D21: =IFERROR(D20^(1/4)-1,"n/a") -> -0.087180778
A23: Read | B23: Business (project) IRR is strong, but investor MOIC depends on entry price. If MOIC < 1x, the pre-money in Funding_Plan (placeholder Rp120B) is above intrinsic equity value — lower it toward the DCF equity value (FD-03). Returns are terminal-value-driven; see Sensitivity_Y5_Breakeven.

Sheet FD_Decision_Log
A1: VOLTLOOP — FOUNDER DECISION LOG
A2: Status is formula-linked to the live model where possible. Priorities: P0 highest. 2026.
A4: ID | B4: Decision | C4: Priority | D4: Action | E4: Target / Metric | F4: Status (live)
A5: FD-11 | B5: Y5 Net Income must reach at least break-even | C5: P1 | D5: Operating levers: VoltOS SaaS, VoltSmart DaaS, anchor fleet, hub price/utilization, opex efficiency, battery lifecycle | E5: Y5 NI ≥ Rp0 | F5: =IF('P&L'!G21>=0,"OK — Y5 NI ≥ 0 (P&L G21, +Rp0.89B)","ACTION PLAN — Y5 NI < 0") -> OK — Y5 NI ≥ 0 (P&L G21, +Rp0.89B)
A6: FD-25 | B6: Mature-hub EBITDA must turn positive before aggressive scale-up | C6: P0 | D6: Fix price / utilization / cost / capex drivers + per-hub platform revenue | E6: Mature hub EBITDA ≥ Rp250M/yr | F6: =IF(Cohort_Economics!C86>=250000000,"TARGET CASE OK (≥Rp250M/hub); live base hub still negative — NEEDS ACTION until proven","NEEDS ACTION") -> TARGET CASE OK (≥Rp250M/hub); live base hub still negative — NEEDS ACTION until proven
A7: FD-17 | B7: Replace placeholder IRR with live scenario IRR | C7: P2 | D7: Built linked scenario FCF + terminal + equity + MOIC + IRR (Scenario_CashFlows) | E7: Live, not placeholder | F7: =IF(ISNUMBER(Scenario_CashFlows!C16),"OK — live scenario IRR, no placeholder","NEEDS REVIEW") -> OK — live scenario IRR, no placeholder
A8: FD-18 | B8: Monthly runway must reconcile to annual model | C8: P2 | D8: Tie monthly revenue/opex/capex/funding/ending cash to annual; label timing | E8: Variance explained or corrected | F8: =IF(Monthly_Runway!F69="OK","OK","WARNING — calibration/timing, see Monthly_Runway") -> WARNING — calibration/timing, see Monthly_Runway
A9: FD-09 | B9: Keep base NPV warning if negative; explain terminal value sensitivity | C9: P1 | D9: Valuation sensitivity added (Sensitivity_Y5_Breakeven); show FD-11 impact | E9: Transparent, not manipulated | F9: OK — sensitivity live
A10: FD-03 | B10: Set pre-money so investor returns are defensible | C10: P1 | D10: Current Rp120B pre-money exceeds DCF equity (~Rp38B base) → investor MOIC <1x | E10: Pre-money ≈ intrinsic equity | F10: =IF(Scenario_CashFlows!C20>=1,"OK","NEEDS REVIEW — Base MOIC < 1x at Rp120B pre-money; lower entry valuation") -> NEEDS REVIEW — Base MOIC < 1x at Rp120B pre-money; lower entry valuation

Sheet Sensitivity_Y5_Breakeven
A1: VOLTLOOP — SENSITIVITY: VALUATION & Y5 BREAK-EVEN
A2: Base-case equity value (with terminal) and Y5 net income, sensitised to key drivers. Live-linked. Center cell = current base assumptions.
A4: TABLE A — Base equity value: WACC (rows) × Exit EV/EBITDA multiple (cols)
B6: WACC \ Exit | C6: 6 | D6: 8 | E6: 10 | F6: 12 | G6: 14
B7: 0.11 | C7: =NPV($B7,Scenario_CashFlows!$C$8:$C$11)+(Scenario_CF!$G$32+C$6*Scenario_CashFlows!$C$6)/(1+$B7)^5+Scenario_CashFlows!$C$14 -> 5.7622221e+09 | D7: =NPV($B7,Scenario_CashFlows!$C$8:$C$11)+(Scenario_CF!$G$32+D$6*Scenario_CashFlows!$C$6)/(1+$B7)^5+Scenario_CashFlows!$C$14 -> 2.8284584e+10 | E7: =NPV($B7,Scenario_CashFlows!$C$8:$C$11)+(Scenario_CF!$G$32+E$6*Scenario_CashFlows!$C$6)/(1+$B7)^5+Scenario_CashFlows!$C$14 -> 5.0806947e+10 | F7: =NPV($B7,Scenario_CashFlows!$C$8:$C$11)+(Scenario_CF!$G$32+F$6*Scenario_CashFlows!$C$6)/(1+$B7)^5+Scenario_CashFlows!$C$14 -> 7.3329309e+10 | G7: =NPV($B7,Scenario_CashFlows!$C$8:$C$11)+(Scenario_CF!$G$32+G$6*Scenario_CashFlows!$C$6)/(1+$B7)^5+Scenario_CashFlows!$C$14 -> 9.5851671e+10
B8: 0.13 | C8: =NPV($B8,Scenario_CashFlows!$C$8:$C$11)+(Scenario_CF!$G$32+C$6*Scenario_CashFlows!$C$6)/(1+$B8)^5+Scenario_CashFlows!$C$14 -> 3.1740644e+09 | D8: =NPV($B8,Scenario_CashFlows!$C$8:$C$11)+(Scenario_CF!$G$32+D$6*Scenario_CashFlows!$C$6)/(1+$B8)^5+Scenario_CashFlows!$C$14 -> 2.3772613e+10 | E8: =NPV($B8,Scenario_CashFlows!$C$8:$C$11)+(Scenario_CF!$G$32+E$6*Scenario_CashFlows!$C$6)/(1+$B8)^5+Scenario_CashFlows!$C$14 -> 4.4371161e+10 | F8: =NPV($B8,Scenario_CashFlows!$C$8:$C$11)+(Scenario_CF!$G$32+F$6*Scenario_CashFlows!$C$6)/(1+$B8)^5+Scenario_CashFlows!$C$14 -> 6.4969709e+10 | G8: =NPV($B8,Scenario_CashFlows!$C$8:$C$11)+(Scenario_CF!$G$32+G$6*Scenario_CashFlows!$C$6)/(1+$B8)^5+Scenario_CashFlows!$C$14 -> 8.5568258e+10
B9: 0.1507 | C9: =NPV($B9,Scenario_CashFlows!$C$8:$C$11)+(Scenario_CF!$G$32+C$6*Scenario_CashFlows!$C$6)/(1+$B9)^5+Scenario_CashFlows!$C$14 -> 8.299791e+08 | D9: =NPV($B9,Scenario_CashFlows!$C$8:$C$11)+(Scenario_CF!$G$32+D$6*Scenario_CashFlows!$C$6)/(1+$B9)^5+Scenario_CashFlows!$C$14 -> 1.9641256e+10 | E9: =NPV($B9,Scenario_CashFlows!$C$8:$C$11)+(Scenario_CF!$G$32+E$6*Scenario_CashFlows!$C$6)/(1+$B9)^5+Scenario_CashFlows!$C$14 -> 3.8452532e+10 | F9: =NPV($B9,Scenario_CashFlows!$C$8:$C$11)+(Scenario_CF!$G$32+F$6*Scenario_CashFlows!$C$6)/(1+$B9)^5+Scenario_CashFlows!$C$14 -> 5.7263809e+10 | G9: =NPV($B9,Scenario_CashFlows!$C$8:$C$11)+(Scenario_CF!$G$32+G$6*Scenario_CashFlows!$C$6)/(1+$B9)^5+Scenario_CashFlows!$C$14 -> 7.6075085e+10
B10: 0.17 | C10: =NPV($B10,Scenario_CashFlows!$C$8:$C$11)+(Scenario_CF!$G$32+C$6*Scenario_CashFlows!$C$6)/(1+$B10)^5+Scenario_CashFlows!$C$14 -> -1.0880481e+09 | D10: =NPV($B10,Scenario_CashFlows!$C$8:$C$11)+(Scenario_CF!$G$32+D$6*Scenario_CashFlows!$C$6)/(1+$B10)^5+Scenario_CashFlows!$C$14 -> 1.622205e+10 | E10: =NPV($B10,Scenario_CashFlows!$C$8:$C$11)+(Scenario_CF!$G$32+E$6*Scenario_CashFlows!$C$6)/(1+$B10)^5+Scenario_CashFlows!$C$14 -> 3.3532148e+10 | F10: =NPV($B10,Scenario_CashFlows!$C$8:$C$11)+(Scenario_CF!$G$32+F$6*Scenario_CashFlows!$C$6)/(1+$B10)^5+Scenario_CashFlows!$C$14 -> 5.0842246e+10 | G10: =NPV($B10,Scenario_CashFlows!$C$8:$C$11)+(Scenario_CF!$G$32+G$6*Scenario_CashFlows!$C$6)/(1+$B10)^5+Scenario_CashFlows!$C$14 -> 6.8152343e+10
B11: 0.19 | C11: =NPV($B11,Scenario_CashFlows!$C$8:$C$11)+(Scenario_CF!$G$32+C$6*Scenario_CashFlows!$C$6)/(1+$B11)^5+Scenario_CashFlows!$C$14 -> -2.8376192e+09 | D11: =NPV($B11,Scenario_CashFlows!$C$8:$C$11)+(Scenario_CF!$G$32+D$6*Scenario_CashFlows!$C$6)/(1+$B11)^5+Scenario_CashFlows!$C$14 -> 1.3065929e+10 | E11: =NPV($B11,Scenario_CashFlows!$C$8:$C$11)+(Scenario_CF!$G$32+E$6*Scenario_CashFlows!$C$6)/(1+$B11)^5+Scenario_CashFlows!$C$14 -> 2.8969477e+10 | F11: =NPV($B11,Scenario_CashFlows!$C$8:$C$11)+(Scenario_CF!$G$32+F$6*Scenario_CashFlows!$C$6)/(1+$B11)^5+Scenario_CashFlows!$C$14 -> 4.4873025e+10 | G11: =NPV($B11,Scenario_CashFlows!$C$8:$C$11)+(Scenario_CF!$G$32+G$6*Scenario_CashFlows!$C$6)/(1+$B11)^5+Scenario_CashFlows!$C$14 -> 6.0776573e+10
A14: TABLE B — Y5 Net Income vs total operating improvement (FD-11 levers)
B15: Improvement (Rp) | C15: 4000000000 | D15: 5000000000 | E15: 5513168651 | F15: 6659000000 | G15: 8000000000
B16: Y5 Net Income | C16: =(-5513168651+C15)-MAX(0,-5513168651+C15)*TaxRate -> -1513168651 | D16: =(-5513168651+D15)-MAX(0,-5513168651+D15)*TaxRate -> -513168651 | E16: =(-5513168651+E15)-MAX(0,-5513168651+E15)*TaxRate -> 0 | F16: =(-5513168651+F15)-MAX(0,-5513168651+F15)*TaxRate -> 8.9374845e+08 | G16: =(-5513168651+G15)-MAX(0,-5513168651+G15)*TaxRate -> 1.9397285e+09
B17: Status | C17: =IF(C16>=0,"OK","below break-even") -> below break-even | D17: =IF(D16>=0,"OK","below break-even") -> below break-even | E17: =IF(E16>=0,"OK","below break-even") -> OK | F17: =IF(F16>=0,"OK","below break-even") -> OK | G17: =IF(G16>=0,"OK","below break-even") -> OK
A19: Current plan = Rp6.659B improvement (green col) → Y5 NI ≈ +Rp0.89B. Break-even threshold ≈ Rp5.513B. FD-11 improvement lifts equity value materially (compare Table A to pre-fix).

Sheet 00_TOC
A1: VOLTLOOP WORKBOOK — TABLE OF CONTENTS | C1: v0.9-audit | DF-0.9 / TRL 3 | 70 sheets | Last updated 12-Jun-2026
A2: Section | B2: Sheets | C2: Color
A3: DASHBOARD | B3: Exec Summary • Audit Report | C3: ● Dark green / Red
A4: BUSINESS PLAN | B4: 00_Cover • 01_Executive_Overview • 02_VMV_Startup • 03_Choices • 04_Market_Sizing • 05_Objektif • 06-10 (Prosbis, Task, Org, RAM) | C4: ● Teal
A5: OPERATIONS | B5: A1_Level4_Activity • A2_E2E_Flow • A3_KPI • A4_Risk_Control • A5_SOP_Draft • A6_Improvement | C5: ● Light blue
A6: MARKET ANALYSIS | B6: Problem • Market • TAM SAM SOM (master) • Customers • Competitors | C6: ● Navy
A7: ASSUMPTIONS | B7: Assumptions (scenario toggle) • Assumptions (2) (fabrication rates) • Master Input Data • Master Component [legacy ref] | C7: ● Orange
A8: ENGINEERING | B8: System_Architecture • Architecture_Trade_Study (48V adopted) • Tech Stack • Requirements_Matrix • ICD_Connector | C8: ● Blue
A9: BOM & COSTING | B9: SBP_BOM • VoltSwap_BOM • VoltGrid_BOM • VoltOS_BOM • Fabrication • RollUp • Cost_Drivers | C9: ● Steel blue
A10: REVENUE & OPS | B10: Pricing • Revenue Model • Swap Hub Econ • Microgrid Econ • Battery Lifecycle • Operational KPI • Carbon • ESG | C10: ● Green
A11: FINANCIAL MODEL | B11: Capex Schedule (+ site build-up + cert budget) • P&L (COGS build wired) • Cash Flow • Balance Sheet • Scenarios (live) • Monthly_Runway (24mo) • Investor Returns (WACC 21%) | C11: ● Purple
A12: RISK & COMPLIANCE | B12: Regulatory_Map (15 regs, SNI critical path) • Uncertainty_Register • Safety_Risk_Register (10 risks) • Procurement_Recs • Procurement_RFQ_List (10 items) | C12: ● Amber
A13: TESTING | B13: Test_Plan (15 TRL4 tests) • Tropical_Test_Protocol (5 tropical tests, 55°C) | C13: ● Teal
... A15: GOVERNANCE | B15: 96_GAP_REGISTER (34 gaps: 23 closed / 4 partial / 7 open) • 97_OPEN_ITEMS • 98_AUDIT_CHECKS (21/21 pass) • 99_CHANGELOG (v0.9-audit, 64 entries) | C15: ● Pink / Green
A17: FORMULA CHAIN (verified)
A18: BOM → RollUp → Capex → Assumptions → Revenue Model → P&L → Cash Flow → Balance Sheet (✅ balanced)
A19: Operational KPI → Exec Summary (✅ correct links: 80 hubs, 60 MGs)
A20: ⚠ Y5 ending cash = -10.1B IDR. Model requires Series B (100B in cap table) or deployment slowdown. See G22/G29 in Gap Register.

Sheet Exec Summary
B1: VOLTLOOP | Executive Summary Dashboard
B2: Indonesia's Circular Battery Infrastructure | Series A Financial Model
B4: Active Scenario: | C4: =Scenario -> Base | E4: Toggle on Assumptions sheet
B6: KEY METRICS — 5 YEAR PROJECTION
B8: Y5 Revenue | C8: Y5 EBITDA | D8: Y5 EBITDA % | E8: 5-Yr IRR | F8: Break-Even | G8: Y5 CO2 Avoided
B9: ='P&L'!G6 -> 6.3947557e+10 | C9: ='P&L'!G15 -> 1.8975745e+10 | D9: ='P&L'!G16 -> 0.29673917 | E9: ='Investor Returns'!C32 -> 0.35801331 | F9: ="Year "&YEAR('P&L'!H17) | G9: =ESG!G10 -> 8962.5
B12: REVENUE TRAJECTORY (5-Year)
C13: Y1 | D13: Y2 | E13: Y3 | F13: Y4 | G13: Y5
B14: Total Revenue | C14: ='P&L'!C6 -> 451723120 | D14: ='P&L'!D6 -> 2980177280 | E14: ='P&L'!E6 -> 1.4115224e+10 | F14: ='P&L'!F6 -> 3.4792139e+10 | G14: ='P&L'!G6 -> 6.3947557e+10
B15: Gross Profit | C15: ='P&L'!C8 -> -176769958 | D15: ='P&L'!D8 -> 268788776 | E15: ='P&L'!E8 -> 4.8439228e+09 | F15: ='P&L'!F8 -> 1.4608822e+10 | G15: ='P&L'!G8 -> 2.8945169e+10
B16: EBITDA | C16: ='P&L'!C15 -> -673665390 | D16: ='P&L'!D15 -> -6.6954984e+08 | E16: ='P&L'!E15 -> 1.0140392e+09 | F16: ='P&L'!F15 -> 7.4385101e+09 | G16: ='P&L'!G15 -> 1.8975745e+10
B17: EBITDA Margin | C17: ='P&L'!C16 -> -1.4913237 | D17: ='P&L'!D16 -> -0.22466779 | E17: ='P&L'!E16 -> 0.071840105 | F17: ='P&L'!F16 -> 0.21379859 | G17: ='P&L'!G16 -> 0.29673917
